 
New instance of bashtop version: 0.9.25 Pid: 33488
 
New instance of bashtop version: 0.9.25 Pid: 33771
 
New instance of bashtop version: 0.9.25 Pid: 41153
 
New instance of bashtop version: 0.9.25 Pid: 41611
 
New instance of bashtop version: 0.9.25 Pid: 6304
Traceback (most recent call last):
  File "/usr/local/lib/python3.9/site-packages/psutil/_common.py", line 447, in wrapper
    ret = self._cache[fun]
AttributeError: 'Process' object has no attribute '_cache'

During handling of the above exception, another exception occurred:

Traceback (most recent call last):
  File "/var/folders/5t/7pln6m5j1z762g4_gg54wnzr0000gn/T//zNbBAo1PxeFR/bashtop.psutil", line 395, in <module>
    exec(command)
  File "<string>", line 1, in <module>
  File "/var/folders/5t/7pln6m5j1z762g4_gg54wnzr0000gn/T//zNbBAo1PxeFR/bashtop.psutil", line 218, in get_proc
    proc_tree(width=prog_len + arg_len, sorting=sort_cmd, reverse=reverse, max_lines=max_lines, proc_per_cpu=proc_per_cpu, search=search)
  File "/var/folders/5t/7pln6m5j1z762g4_gg54wnzr0000gn/T//zNbBAo1PxeFR/bashtop.psutil", line 314, in proc_tree
    tree[p.ppid()].append(p.pid)
  File "/usr/local/lib/python3.9/site-packages/psutil/_common.py", line 450, in wrapper
    return fun(self)
  File "/usr/local/lib/python3.9/site-packages/psutil/__init__.py", line 605, in ppid
    return self._proc.ppid()
KeyboardInterrupt
/usr/local/bin/bashtop: line 4817: ${pycoproc[1]}: ambiguous redirect
20:20:38 ERROR: On line 4817 
/usr/local/bin/bashtop: line 4820: read: -t: invalid file descriptor specification
/usr/local/bin/bashtop: line 4817: ${pycoproc[1]}: ambiguous redirect
20:20:38 ERROR: On line 4817 (MUTED!)
/usr/local/bin/bashtop: line 4820: read: -t: invalid file descriptor specification
/usr/local/bin/bashtop: line 4817: ${pycoproc[1]}: ambiguous redirect
/usr/local/bin/bashtop: line 4820: read: -t: invalid file descriptor specification
/usr/local/bin/bashtop: line 4817: ${pycoproc[1]}: ambiguous redirect
/usr/local/bin/bashtop: line 4820: read: -t: invalid file descriptor specification
/usr/local/bin/bashtop: line 4817: ${pycoproc[1]}: ambiguous redirect
/usr/local/bin/bashtop: line 4820: read: -t: invalid file descriptor specification
/usr/local/bin/bashtop: line 4817: ${pycoproc[1]}: ambiguous redirect
/usr/local/bin/bashtop: line 4820: read: -t: invalid file descriptor specification
/usr/local/bin/bashtop: line 4817: ${pycoproc[1]}: ambiguous redirect
/usr/local/bin/bashtop: line 4820: read: -t: invalid file descriptor specification
/usr/local/bin/bashtop: line 4806: ${pycoproc[1]}: ambiguous redirect
 
New instance of bashtop version: 0.9.25 Pid: 71660
 
New instance of bashtop version: 0.9.25 Pid: 24270
